#VRML_SIM R2023b utf8

EXTERNPROTO "https://raw.githubusercontent.com/cyberbotics/webots/R2023b/projects/objects/backgrounds/protos/TexturedBackground.proto"
EXTERNPROTO "https://raw.githubusercontent.com/cyberbotics/webots/R2023b/projects/objects/backgrounds/protos/TexturedBackgroundLight.proto"
EXTERNPROTO "https://raw.githubusercontent.com/cyberbotics/webots/R2023b/projects/objects/floors/protos/RectangleArena.proto"
EXTERNPROTO "https://raw.githubusercontent.com/cyberbotics/webots/R2023b/projects/appearances/protos/BrushedAluminium.proto"
EXTERNPROTO "https://raw.githubusercontent.com/cyberbotics/webots/R2023b/projects/robots/gctronic/e-puck/protos/E-puck.proto"

WorldInfo {
  info [
    "Example use of a color Camera device."
  ]
  title "Camera"
  basicTimeStep 64
}
Viewpoint {
  orientation -0.5519807914399929 0.5870739212010025 0.5921667137951593 2.1268159661283406
  position 0.8237232186154806 0.030520153712934595 4.304506797738863
}
TexturedBackground {
}
TexturedBackgroundLight {
}
RectangleArena {
  floorSize 2 2
  floorTileSize 4 4
  wallAppearance BrushedAluminium {
    colorOverride 0.180392 0.180392 0.180392
  }
}
DEF robot_1 Robot {
  translation 0.5308882917320903 -0.18734865944533702 -0.00046879855490923605
  rotation -0.011431475581352815 0.217536954744176 0.9759851406075111 0.10658060310605154
  children [
    DistanceSensor {
      translation 0.02 0.042 0.063
      rotation -0.7268299363531201 -0.48565329383260614 -0.48565329383260614 -1.88458
      children [
        DEF SENSOR Pose {
          rotation 0.577656895078166 0.5771968951617173 -0.5771968951617173 -2.093935
          children [
            Shape {
              appearance PBRAppearance {
                baseColor 0.975691 0.981481 0.0252992
                roughness 1
                metalness 0
              }
              geometry Cylinder {
                height 0.004
                radius 0.008
              }
            }
          ]
        }
      ]
      name "ds6"
      lookupTable [
        0 1024 0
        0.05 1024 0
        0.15 0 0
      ]
      numberOfRays 2
      aperture 1
    }
    DistanceSensor {
      translation 0.042 0.02 0.063
      rotation -0.9626362180015103 -0.19148304336382932 -0.19148304336382932 -1.60887
      children [
        DEF SENSOR Pose {
          rotation 0.577656895078166 0.5771968951617173 -0.5771968951617173 -2.093935
          children [
            Shape {
              appearance PBRAppearance {
                baseColor 0.975691 0.981481 0.0252992
                roughness 1
                metalness 0
              }
              geometry Cylinder {
                height 0.004
                radius 0.008
              }
            }
          ]
        }
      ]
      name "ds7"
      lookupTable [
        0 1024 0
        0.05 1024 0
        0.15 0 0
      ]
      numberOfRays 2
      aperture 1
    }
    DistanceSensor {
      translation -0.02 0.042 0.063
      rotation -0.42718918036721304 -0.6393392699409246 -0.6393392699409246 -2.33415
      children [
        USE SENSOR
      ]
      name "ds5"
      lookupTable [
        0 1024 0
        0.05 1024 0
        0.15 0 0
      ]
      numberOfRays 2
      aperture 1
    }
    DistanceSensor {
      translation -0.042 0.02 0.063
      rotation -0.13927796840242873 -0.7002148411443777 -0.7002148411443777 -2.86482
      children [
        USE SENSOR
      ]
      name "ds4"
      lookupTable [
        0 1024 0
        0.05 1024 0
        0.15 0 0
      ]
      numberOfRays 2
      aperture 1
    }
    DistanceSensor {
      translation -0.042 -0.02 0.063
      rotation -0.13928600826049622 0.7002140415268951 0.7002140415268951 -2.8648
      children [
        USE SENSOR
      ]
      name "ds3"
      lookupTable [
        0 1024 0
        0.05 1024 0
        0.15 0 0
      ]
      numberOfRays 2
      aperture 1
    }
    DistanceSensor {
      translation -0.02 -0.042 0.063
      rotation -0.4271968128991576 0.6393367199875204 0.6393367199875204 -2.33413
      children [
        USE SENSOR
      ]
      name "ds2"
      lookupTable [
        0 1024 0
        0.05 1024 0
        0.15 0 0
      ]
      numberOfRays 2
      aperture 1
    }
    Pose {
      translation 0 0 0.0415
      rotation 0 0 1 -1.570796
      children [
        Shape {
          appearance PBRAppearance {
            baseColor 0.0820075 0.364731 0.8
            roughness 1
            metalness 0
          }
          geometry DEF BODY Cylinder {
            height 0.08
            radius 0.045
          }
        }
      ]
    }
    HingeJoint {
      jointParameters HingeJointParameters {
        position 4572.730241605284
        axis 0 1 0
        anchor 0 0 0.025
      }
      device [
        RotationalMotor {
          name "left wheel motor"
          consumptionFactor 70
        }
        PositionSensor {
          name "left wheel sensor"
        }
      ]
      endPoint Solid {
        translation 0 0.04499999999999425 0.025
        rotation 0.60081372578427 -0.6008138634970014 -0.5273002639284665 2.1710953276049434
        children [
          DEF WHEEL Pose {
            rotation 0.577656895078166 0.5771968951617173 -0.5771968951617173 -2.093935
            children [
              Shape {
                appearance PBRAppearance {
                  baseColor 1 0 0
                  roughness 1
                  metalness 0
                }
                geometry Cylinder {
                  height 0.01
                  radius 0.025
                }
              }
            ]
          }
        ]
        name "left wheel"
        boundingObject USE WHEEL
        physics DEF PHYSICS_WHEEL Physics {
          density -1
          mass 0.05
        }
      }
    }
    HingeJoint {
      jointParameters HingeJointParameters {
        position 5159.818620828564
        axis 0 1 0
        anchor 0 0 0.025
      }
      device [
        RotationalMotor {
          name "right wheel motor"
          consumptionFactor 70
        }
        PositionSensor {
          name "right wheel sensor"
        }
      ]
      endPoint Solid {
        translation 0 -0.0449999999999932 0.025
        rotation 0.5523407638516942 -0.5523407183071546 0.6243712128915486 4.257886621528002
        children [
          USE WHEEL
        ]
        name "right wheel"
        boundingObject USE WHEEL
        physics USE PHYSICS_WHEEL
      }
    }
    DistanceSensor {
      translation 0.042 -0.02 0.063
      rotation -0.9626378392751118 0.19147896803009973 0.19147896803009973 -1.60886
      children [
        DEF SENSOR Pose {
          rotation 0.577656895078166 0.5771968951617173 -0.5771968951617173 -2.093935
          children [
            Shape {
              appearance PBRAppearance {
                baseColor 0.975691 0.981481 0.0252992
                roughness 1
                metalness 0
              }
              geometry Cylinder {
                height 0.004
                radius 0.008
              }
            }
          ]
        }
      ]
      name "ds0"
      lookupTable [
        0 1024 0
        0.05 1024 0
        0.15 0 0
      ]
      aperture 1
    }
    DistanceSensor {
      translation 0.02 -0.042 0.063
      rotation -0.7268313515069925 0.4856522348690052 0.4856522348690052 -1.88458
      children [
        USE SENSOR
      ]
      name "ds1"
      lookupTable [
        0 1024 0
        0.05 1024 0
        0.15 0 0
      ]
      numberOfRays 2
      aperture 1
    }
    DEF SMILE Pose {
      translation 0.036 0 0.025
      rotation 0.25056300542381216 -0.9351130202419243 -0.25056300542381216 1.637834
      children [
        Shape {
          appearance PBRAppearance {
            baseColor 0.721569 0.290196 0.290196
            roughness 1
            metalness 0
          }
          geometry Cylinder {
            height 0.018
            radius 0.009
            subdivision 3
          }
        }
      ]
    }
  ]
  name "robot_1"
  boundingObject Pose {
    translation 0 0 0.0415
    rotation 0 0 1 -1.570796
    children [
      USE BODY
    ]
  }
  physics Physics {
    density -1
    mass 0.5
  }
  controller "robot_controller"
}
DEF robot_3 Robot {
  translation 0.29266294847518404 0.8579014480248478 -0.0004798722831447916
  rotation 0.011449965682000105 0.001823575346333969 0.9999327841704346 -2.8495484387069188
  children [
    DistanceSensor {
      translation 0.02 0.042 0.063
      rotation -0.7268299363531201 -0.48565329383260614 -0.48565329383260614 -1.88458
      children [
        DEF SENSOR Pose {
          rotation 0.577656895078166 0.5771968951617173 -0.5771968951617173 -2.093935
          children [
            Shape {
              appearance PBRAppearance {
                baseColor 0.975691 0.981481 0.0252992
                roughness 1
                metalness 0
              }
              geometry Cylinder {
                height 0.004
                radius 0.008
              }
            }
          ]
        }
      ]
      name "ds6"
      lookupTable [
        0 1024 0
        0.05 1024 0
        0.15 0 0
      ]
      numberOfRays 2
      aperture 1
    }
    DistanceSensor {
      translation 0.042 0.02 0.063
      rotation -0.9626362180015103 -0.19148304336382932 -0.19148304336382932 -1.60887
      children [
        DEF SENSOR Pose {
          rotation 0.577656895078166 0.5771968951617173 -0.5771968951617173 -2.093935
          children [
            Shape {
              appearance PBRAppearance {
                baseColor 0.975691 0.981481 0.0252992
                roughness 1
                metalness 0
              }
              geometry Cylinder {
                height 0.004
                radius 0.008
              }
            }
          ]
        }
      ]
      name "ds7"
      lookupTable [
        0 1024 0
        0.05 1024 0
        0.15 0 0
      ]
      numberOfRays 2
      aperture 1
    }
    DistanceSensor {
      translation -0.02 0.042 0.063
      rotation -0.42718918036721304 -0.6393392699409246 -0.6393392699409246 -2.33415
      children [
        USE SENSOR
      ]
      name "ds5"
      lookupTable [
        0 1024 0
        0.05 1024 0
        0.15 0 0
      ]
      numberOfRays 2
      aperture 1
    }
    DistanceSensor {
      translation -0.042 0.02 0.063
      rotation -0.13927796840242873 -0.7002148411443777 -0.7002148411443777 -2.86482
      children [
        USE SENSOR
      ]
      name "ds4"
      lookupTable [
        0 1024 0
        0.05 1024 0
        0.15 0 0
      ]
      numberOfRays 2
      aperture 1
    }
    DistanceSensor {
      translation -0.042 -0.02 0.063
      rotation -0.13928600826049622 0.7002140415268951 0.7002140415268951 -2.8648
      children [
        USE SENSOR
      ]
      name "ds3"
      lookupTable [
        0 1024 0
        0.05 1024 0
        0.15 0 0
      ]
      numberOfRays 2
      aperture 1
    }
    DistanceSensor {
      translation -0.02 -0.042 0.063
      rotation -0.4271968128991576 0.6393367199875204 0.6393367199875204 -2.33413
      children [
        USE SENSOR
      ]
      name "ds2"
      lookupTable [
        0 1024 0
        0.05 1024 0
        0.15 0 0
      ]
      numberOfRays 2
      aperture 1
    }
    Pose {
      translation 0 0 0.0415
      rotation 0 0 1 -1.570796
      children [
        Shape {
          appearance PBRAppearance {
            baseColor 0.0820075 0.364731 0.8
            roughness 1
            metalness 0
          }
          geometry DEF BODY Cylinder {
            height 0.08
            radius 0.045
          }
        }
      ]
    }
    HingeJoint {
      jointParameters HingeJointParameters {
        position 4583.85677817723
        axis 0 1 0
        anchor 0 0 0.025
      }
      device [
        RotationalMotor {
          name "left wheel motor"
          consumptionFactor 70
        }
        PositionSensor {
          name "left wheel sensor"
        }
      ]
      endPoint Solid {
        translation -1.3450199442325833e-17 0.04499999999999478 0.024999999999999998
        rotation 0.7071066596199304 -0.7071068438344368 -0.00028865835430251426 3.14101528627385
        children [
          DEF WHEEL Pose {
            rotation 0.577656895078166 0.5771968951617173 -0.5771968951617173 -2.093935
            children [
              Shape {
                appearance PBRAppearance {
                  baseColor 1 0 0
                  roughness 1
                  metalness 0
                }
                geometry Cylinder {
                  height 0.01
                  radius 0.025
                }
              }
            ]
          }
        ]
        name "left wheel"
        boundingObject USE WHEEL
        physics DEF PHYSICS_WHEEL Physics {
          density -1
          mass 0.05
        }
      }
    }
    HingeJoint {
      jointParameters HingeJointParameters {
        position 5184.051194110793
        axis 0 1 0
        anchor 0 0 0.025
      }
      device [
        RotationalMotor {
          name "right wheel motor"
          consumptionFactor 70
        }
        PositionSensor {
          name "right wheel sensor"
        }
      ]
      endPoint Solid {
        translation -7.018871730562957e-18 -0.04499999999999314 0.02500000000000001
        rotation 0.2613449579045604 -0.26134493987532326 0.9291919260192842 4.639014849696375
        children [
          USE WHEEL
        ]
        name "right wheel"
        boundingObject USE WHEEL
        physics USE PHYSICS_WHEEL
      }
    }
    DistanceSensor {
      translation 0.042 -0.02 0.063
      rotation -0.9626378392751118 0.19147896803009973 0.19147896803009973 -1.60886
      children [
        DEF SENSOR Pose {
          rotation 0.577656895078166 0.5771968951617173 -0.5771968951617173 -2.093935
          children [
            Shape {
              appearance PBRAppearance {
                baseColor 0.975691 0.981481 0.0252992
                roughness 1
                metalness 0
              }
              geometry Cylinder {
                height 0.004
                radius 0.008
              }
            }
          ]
        }
      ]
      name "ds0"
      lookupTable [
        0 1024 0
        0.05 1024 0
        0.15 0 0
      ]
      aperture 1
    }
    DistanceSensor {
      translation 0.02 -0.042 0.063
      rotation -0.7268313515069925 0.4856522348690052 0.4856522348690052 -1.88458
      children [
        USE SENSOR
      ]
      name "ds1"
      lookupTable [
        0 1024 0
        0.05 1024 0
        0.15 0 0
      ]
      numberOfRays 2
      aperture 1
    }
    DEF SMILE Pose {
      translation 0.036 0 0.025
      rotation 0.25056300542381216 -0.9351130202419243 -0.25056300542381216 1.637834
      children [
        Shape {
          appearance PBRAppearance {
            baseColor 0.721569 0.290196 0.290196
            roughness 1
            metalness 0
          }
          geometry Cylinder {
            height 0.018
            radius 0.009
            subdivision 3
          }
        }
      ]
    }
  ]
  name "robot_3"
  boundingObject Pose {
    translation 0 0 0.0415
    rotation 0 0 1 -1.570796
    children [
      USE BODY
    ]
  }
  physics Physics {
    density -1
    mass 0.5
  }
  controller "robot_controller"
}
DEF robot_4 Robot {
  translation -0.8670902699315551 0.5333261601422303 -0.00046859412525093735
  rotation -0.01160412695625225 -0.011780394645858887 0.9998632739227755 -1.555958889322059
  children [
    DistanceSensor {
      translation 0.02 0.042 0.063
      rotation -0.7268299363531201 -0.48565329383260614 -0.48565329383260614 -1.88458
      children [
        DEF SENSOR Pose {
          rotation 0.577656895078166 0.5771968951617173 -0.5771968951617173 -2.093935
          children [
            Shape {
              appearance PBRAppearance {
                baseColor 0.975691 0.981481 0.0252992
                roughness 1
                metalness 0
              }
              geometry Cylinder {
                height 0.004
                radius 0.008
              }
            }
          ]
        }
      ]
      name "ds6"
      lookupTable [
        0 1024 0
        0.05 1024 0
        0.15 0 0
      ]
      numberOfRays 2
      aperture 1
    }
    DistanceSensor {
      translation 0.042 0.02 0.063
      rotation -0.9626362180015103 -0.19148304336382932 -0.19148304336382932 -1.60887
      children [
        DEF SENSOR Pose {
          rotation 0.577656895078166 0.5771968951617173 -0.5771968951617173 -2.093935
          children [
            Shape {
              appearance PBRAppearance {
                baseColor 0.975691 0.981481 0.0252992
                roughness 1
                metalness 0
              }
              geometry Cylinder {
                height 0.004
                radius 0.008
              }
            }
          ]
        }
      ]
      name "ds7"
      lookupTable [
        0 1024 0
        0.05 1024 0
        0.15 0 0
      ]
      numberOfRays 2
      aperture 1
    }
    DistanceSensor {
      translation -0.02 0.042 0.063
      rotation -0.42718918036721304 -0.6393392699409246 -0.6393392699409246 -2.33415
      children [
        USE SENSOR
      ]
      name "ds5"
      lookupTable [
        0 1024 0
        0.05 1024 0
        0.15 0 0
      ]
      numberOfRays 2
      aperture 1
    }
    DistanceSensor {
      translation -0.042 0.02 0.063
      rotation -0.13927796840242873 -0.7002148411443777 -0.7002148411443777 -2.86482
      children [
        USE SENSOR
      ]
      name "ds4"
      lookupTable [
        0 1024 0
        0.05 1024 0
        0.15 0 0
      ]
      numberOfRays 2
      aperture 1
    }
    DistanceSensor {
      translation -0.042 -0.02 0.063
      rotation -0.13928600826049622 0.7002140415268951 0.7002140415268951 -2.8648
      children [
        USE SENSOR
      ]
      name "ds3"
      lookupTable [
        0 1024 0
        0.05 1024 0
        0.15 0 0
      ]
      numberOfRays 2
      aperture 1
    }
    DistanceSensor {
      translation -0.02 -0.042 0.063
      rotation -0.4271968128991576 0.6393367199875204 0.6393367199875204 -2.33413
      children [
        USE SENSOR
      ]
      name "ds2"
      lookupTable [
        0 1024 0
        0.05 1024 0
        0.15 0 0
      ]
      numberOfRays 2
      aperture 1
    }
    Pose {
      translation 0 0 0.0415
      rotation 0 0 1 -1.570796
      children [
        Shape {
          appearance PBRAppearance {
            baseColor 0.0820075 0.364731 0.8
            roughness 1
            metalness 0
          }
          geometry DEF BODY Cylinder {
            height 0.08
            radius 0.045
          }
        }
      ]
    }
    HingeJoint {
      jointParameters HingeJointParameters {
        position 4562.4113543641215
        axis 0 1 0
        anchor 0 0 0.025
      }
      device [
        RotationalMotor {
          name "left wheel motor"
          consumptionFactor 70
        }
        PositionSensor {
          name "left wheel sensor"
        }
      ]
      endPoint Solid {
        translation 1.1708232887293504e-17 0.044999999999993615 0.024999999999999974
        rotation -0.2605597676724227 0.2605598687353041 -0.9296328104553615 1.643697016692543
        children [
          DEF WHEEL Pose {
            rotation 0.577656895078166 0.5771968951617173 -0.5771968951617173 -2.093935
            children [
              Shape {
                appearance PBRAppearance {
                  baseColor 1 0 0
                  roughness 1
                  metalness 0
                }
                geometry Cylinder {
                  height 0.01
                  radius 0.025
                }
              }
            ]
          }
        ]
        name "left wheel"
        boundingObject USE WHEEL
        physics DEF PHYSICS_WHEEL Physics {
          density -1
          mass 0.05
        }
      }
    }
    HingeJoint {
      jointParameters HingeJointParameters {
        position 5167.718152848571
        axis 0 1 0
        anchor 0 0 0.025
      }
      device [
        RotationalMotor {
          name "right wheel motor"
          consumptionFactor 70
        }
        PositionSensor {
          name "right wheel sensor"
        }
      ]
      endPoint Solid {
        translation 1.4788402809454886e-17 -0.04499999999999383 0.025000000000000022
        rotation -0.7068465506967682 0.7068464881242063 -0.02712924611111772 3.087347479495181
        children [
          USE WHEEL
        ]
        name "right wheel"
        boundingObject USE WHEEL
        physics USE PHYSICS_WHEEL
      }
    }
    DistanceSensor {
      translation 0.042 -0.02 0.063
      rotation -0.9626378392751118 0.19147896803009973 0.19147896803009973 -1.60886
      children [
        DEF SENSOR Pose {
          rotation 0.577656895078166 0.5771968951617173 -0.5771968951617173 -2.093935
          children [
            Shape {
              appearance PBRAppearance {
                baseColor 0.975691 0.981481 0.0252992
                roughness 1
                metalness 0
              }
              geometry Cylinder {
                height 0.004
                radius 0.008
              }
            }
          ]
        }
      ]
      name "ds0"
      lookupTable [
        0 1024 0
        0.05 1024 0
        0.15 0 0
      ]
      aperture 1
    }
    DistanceSensor {
      translation 0.02 -0.042 0.063
      rotation -0.7268313515069925 0.4856522348690052 0.4856522348690052 -1.88458
      children [
        USE SENSOR
      ]
      name "ds1"
      lookupTable [
        0 1024 0
        0.05 1024 0
        0.15 0 0
      ]
      numberOfRays 2
      aperture 1
    }
    DEF SMILE Pose {
      translation 0.036 0 0.025
      rotation 0.25056300542381216 -0.9351130202419243 -0.25056300542381216 1.637834
      children [
        Shape {
          appearance PBRAppearance {
            baseColor 0.721569 0.290196 0.290196
            roughness 1
            metalness 0
          }
          geometry Cylinder {
            height 0.018
            radius 0.009
            subdivision 3
          }
        }
      ]
    }
  ]
  name "robot_4"
  boundingObject Pose {
    translation 0 0 0.0415
    rotation 0 0 1 -1.570796
    children [
      USE BODY
    ]
  }
  physics Physics {
    density -1
    mass 0.5
  }
  controller "robot_controller"
}
DEF robot_2 Robot {
  translation 0.4084735367848683 -0.8596481110955266 -0.0004685249971914385
  rotation 0.0071041623091812655 0.8064508890915607 0.5912583989773978 -0.028790632283299367
  children [
    DistanceSensor {
      translation 0.02 0.042 0.063
      rotation -0.7268299363531201 -0.48565329383260614 -0.48565329383260614 -1.88458
      children [
        DEF SENSOR Pose {
          rotation 0.577656895078166 0.5771968951617173 -0.5771968951617173 -2.093935
          children [
            Shape {
              appearance PBRAppearance {
                baseColor 0.975691 0.981481 0.0252992
                roughness 1
                metalness 0
              }
              geometry Cylinder {
                height 0.004
                radius 0.008
              }
            }
          ]
        }
      ]
      name "ds6"
      lookupTable [
        0 1024 0
        0.05 1024 0
        0.15 0 0
      ]
      numberOfRays 2
      aperture 1
    }
    DistanceSensor {
      translation 0.042 0.02 0.063
      rotation -0.9626362180015103 -0.19148304336382932 -0.19148304336382932 -1.60887
      children [
        DEF SENSOR Pose {
          rotation 0.577656895078166 0.5771968951617173 -0.5771968951617173 -2.093935
          children [
            Shape {
              appearance PBRAppearance {
                baseColor 0.975691 0.981481 0.0252992
                roughness 1
                metalness 0
              }
              geometry Cylinder {
                height 0.004
                radius 0.008
              }
            }
          ]
        }
      ]
      name "ds7"
      lookupTable [
        0 1024 0
        0.05 1024 0
        0.15 0 0
      ]
      numberOfRays 2
      aperture 1
    }
    DistanceSensor {
      translation -0.02 0.042 0.063
      rotation -0.42718918036721304 -0.6393392699409246 -0.6393392699409246 -2.33415
      children [
        USE SENSOR
      ]
      name "ds5"
      lookupTable [
        0 1024 0
        0.05 1024 0
        0.15 0 0
      ]
      numberOfRays 2
      aperture 1
    }
    DistanceSensor {
      translation -0.042 0.02 0.063
      rotation -0.13927796840242873 -0.7002148411443777 -0.7002148411443777 -2.86482
      children [
        USE SENSOR
      ]
      name "ds4"
      lookupTable [
        0 1024 0
        0.05 1024 0
        0.15 0 0
      ]
      numberOfRays 2
      aperture 1
    }
    DistanceSensor {
      translation -0.042 -0.02 0.063
      rotation -0.13928600826049622 0.7002140415268951 0.7002140415268951 -2.8648
      children [
        USE SENSOR
      ]
      name "ds3"
      lookupTable [
        0 1024 0
        0.05 1024 0
        0.15 0 0
      ]
      numberOfRays 2
      aperture 1
    }
    DistanceSensor {
      translation -0.02 -0.042 0.063
      rotation -0.4271968128991576 0.6393367199875204 0.6393367199875204 -2.33413
      children [
        USE SENSOR
      ]
      name "ds2"
      lookupTable [
        0 1024 0
        0.05 1024 0
        0.15 0 0
      ]
      numberOfRays 2
      aperture 1
    }
    Pose {
      translation 0 0 0.0415
      rotation 0 0 1 -1.570796
      children [
        Shape {
          appearance PBRAppearance {
            baseColor 0.0820075 0.364731 0.8
            roughness 1
            metalness 0
          }
          geometry DEF BODY Cylinder {
            height 0.08
            radius 0.045
          }
        }
      ]
    }
    HingeJoint {
      jointParameters HingeJointParameters {
        position 4106.066381890248
        axis 0 1 0
        anchor 0 0 0.025
      }
      device [
        RotationalMotor {
          name "left wheel motor"
          consumptionFactor 70
        }
        PositionSensor {
          name "left wheel sensor"
        }
      ]
      endPoint Solid {
        translation 0 0.04499999999999389 0.025
        rotation 0.7039278687061716 -0.7039280554831425 0.09471456256832157 3.330458360691477
        children [
          DEF WHEEL Pose {
            rotation 0.577656895078166 0.5771968951617173 -0.5771968951617173 -2.093935
            children [
              Shape {
                appearance PBRAppearance {
                  baseColor 1 0 0
                  roughness 1
                  metalness 0
                }
                geometry Cylinder {
                  height 0.01
                  radius 0.025
                }
              }
            ]
          }
        ]
        name "left wheel"
        boundingObject USE WHEEL
        physics DEF PHYSICS_WHEEL Physics {
          density -1
          mass 0.05
        }
      }
    }
    HingeJoint {
      jointParameters HingeJointParameters {
        position 5520.9375786356695
        axis 0 1 0
        anchor 0 0 0.025
      }
      device [
        RotationalMotor {
          name "right wheel motor"
          consumptionFactor 70
        }
        PositionSensor {
          name "right wheel sensor"
        }
      ]
      endPoint Solid {
        translation 0 -0.044999999999993046 0.025
        rotation -0.6250769378219262 0.6250768797576578 0.46750156812100074 4.016217660569984
        children [
          USE WHEEL
        ]
        name "right wheel"
        boundingObject USE WHEEL
        physics USE PHYSICS_WHEEL
      }
    }
    DistanceSensor {
      translation 0.042 -0.02 0.063
      rotation -0.9626378392751118 0.19147896803009973 0.19147896803009973 -1.60886
      children [
        DEF SENSOR Pose {
          rotation 0.577656895078166 0.5771968951617173 -0.5771968951617173 -2.093935
          children [
            Shape {
              appearance PBRAppearance {
                baseColor 0.975691 0.981481 0.0252992
                roughness 1
                metalness 0
              }
              geometry Cylinder {
                height 0.004
                radius 0.008
              }
            }
          ]
        }
      ]
      name "ds0"
      lookupTable [
        0 1024 0
        0.05 1024 0
        0.15 0 0
      ]
      aperture 1
    }
    DistanceSensor {
      translation 0.02 -0.042 0.063
      rotation -0.7268313515069925 0.4856522348690052 0.4856522348690052 -1.88458
      children [
        USE SENSOR
      ]
      name "ds1"
      lookupTable [
        0 1024 0
        0.05 1024 0
        0.15 0 0
      ]
      numberOfRays 2
      aperture 1
    }
    DEF SMILE Pose {
      translation 0.036 0 0.025
      rotation 0.25056300542381216 -0.9351130202419243 -0.25056300542381216 1.637834
      children [
        Shape {
          appearance PBRAppearance {
            baseColor 0.721569 0.290196 0.290196
            roughness 1
            metalness 0
          }
          geometry Cylinder {
            height 0.018
            radius 0.009
            subdivision 3
          }
        }
      ]
    }
  ]
  name "robot_2"
  boundingObject Pose {
    translation 0 0 0.0415
    rotation 0 0 1 -1.570796
    children [
      USE BODY
    ]
  }
  physics Physics {
    density -1
    mass 0.5
  }
  controller "robot_controller"
}
Robot {
  translation 0 0 0.001
  children [
    Display {
      children [
        Shape {
          appearance PBRAppearance {
            baseColorMap ImageTexture {
            }
            roughness 1
          }
          geometry Plane {
            size 2 2
          }
        }
      ]
    }
  ]
  name "supervisor"
  controller "Robot_Supervisor_Extended"
  supervisor TRUE
}
Solid {
  translation 0.107907 0.500187 0.05
  children [
    Shape {
      appearance PBRAppearance {
        baseColor 0 0 0
        metalness 0
      }
      geometry Box {
        size 0.05 1 0.1
      }
    }
  ]
  boundingObject Box {
    size 0.05 1 0.1
  }
}
Solid {
  translation -0.169068 -0.654144 0.05
  rotation 0 0 1 -3.1415853071795863
  children [
    Shape {
      appearance PBRAppearance {
        baseColor 0 0 0
        metalness 0
      }
      geometry Box {
        size 0.05 0.7 0.1
      }
    }
  ]
  name "solid(2)"
  boundingObject Box {
    size 0.05 0.7 0.1
  }
}
Solid {
  translation 0.6481 -0.345055 0.05
  rotation 0 0 -1 1.57079
  children [
    Shape {
      appearance PBRAppearance {
        baseColor 0 0 0
        metalness 0
      }
      geometry Box {
        size 0.05 0.7 0.1
      }
    }
  ]
  name "solid(3)"
  boundingObject Box {
    size 0.05 0.7 0.1
  }
}
E-puck {
  hidden position_0_0 43.719272654991514
  hidden position_0_1 40.90791521010968
  hidden rotation_1 0 1 0 6.020160811913995
  hidden rotation_2 0 1 0 3.2088033670321594
  translation -0.41536989886462233 -0.3815447882208337 -0.00011386280899129339
  rotation -1.696751360861854e-06 -4.735576450582552e-06 0.9999999999873477 0.9143127854918256
  controller "rrt_star_heuristic"
  turretSlot [
    InertialUnit {
    }
    GPS {
    }
  ]
}
