#VRML_SIM R2023b utf8

EXTERNPROTO "https://raw.githubusercontent.com/cyberbotics/webots/R2023b/projects/objects/backgrounds/protos/TexturedBackground.proto"
EXTERNPROTO "https://raw.githubusercontent.com/cyberbotics/webots/R2023b/projects/objects/backgrounds/protos/TexturedBackgroundLight.proto"
EXTERNPROTO "https://raw.githubusercontent.com/cyberbotics/webots/R2023b/projects/objects/floors/protos/RectangleArena.proto"
EXTERNPROTO "https://raw.githubusercontent.com/cyberbotics/webots/R2023b/projects/appearances/protos/BrushedAluminium.proto"
EXTERNPROTO "https://raw.githubusercontent.com/cyberbotics/webots/R2023b/projects/robots/gctronic/e-puck/protos/E-puck.proto"

WorldInfo {
  info [
    "Example use of a color Camera device."
  ]
  title "Camera"
  basicTimeStep 64
}
Viewpoint {
  orientation -0.5540156742155815 0.592338940708899 0.5849796680597662 2.132720174656545
  position 0.8765742223121249 0.06920782210920091 4.265755881960527
}
TexturedBackground {
}
TexturedBackgroundLight {
}
RectangleArena {
  floorSize 2 2
  floorTileSize 4 4
  wallAppearance BrushedAluminium {
    colorOverride 0.180392 0.180392 0.180392
  }
}
DEF robot_1 Robot {
  translation 0.4874073728571147 -0.5108445443659374 -0.00046856116668248654
  rotation 0.011608631434386271 1.4422035982465722e-05 0.9999326174639096 -3.1385158530378026
  children [
    DistanceSensor {
      translation 0.02 0.042 0.063
      rotation -0.7268299363531201 -0.48565329383260614 -0.48565329383260614 -1.88458
      children [
        DEF SENSOR Pose {
          rotation 0.577656895078166 0.5771968951617173 -0.5771968951617173 -2.093935
          children [
            Shape {
              appearance PBRAppearance {
                baseColor 0.975691 0.981481 0.0252992
                roughness 1
                metalness 0
              }
              geometry Cylinder {
                height 0.004
                radius 0.008
              }
            }
          ]
        }
      ]
      name "ds6"
      lookupTable [
        0 1024 0
        0.05 1024 0
        0.15 0 0
      ]
      numberOfRays 2
      aperture 1
    }
    DistanceSensor {
      translation 0.042 0.02 0.063
      rotation -0.9626362180015103 -0.19148304336382932 -0.19148304336382932 -1.60887
      children [
        DEF SENSOR Pose {
          rotation 0.577656895078166 0.5771968951617173 -0.5771968951617173 -2.093935
          children [
            Shape {
              appearance PBRAppearance {
                baseColor 0.975691 0.981481 0.0252992
                roughness 1
                metalness 0
              }
              geometry Cylinder {
                height 0.004
                radius 0.008
              }
            }
          ]
        }
      ]
      name "ds7"
      lookupTable [
        0 1024 0
        0.05 1024 0
        0.15 0 0
      ]
      numberOfRays 2
      aperture 1
    }
    DistanceSensor {
      translation -0.02 0.042 0.063
      rotation -0.42718918036721304 -0.6393392699409246 -0.6393392699409246 -2.33415
      children [
        USE SENSOR
      ]
      name "ds5"
      lookupTable [
        0 1024 0
        0.05 1024 0
        0.15 0 0
      ]
      numberOfRays 2
      aperture 1
    }
    DistanceSensor {
      translation -0.042 0.02 0.063
      rotation -0.13927796840242873 -0.7002148411443777 -0.7002148411443777 -2.86482
      children [
        USE SENSOR
      ]
      name "ds4"
      lookupTable [
        0 1024 0
        0.05 1024 0
        0.15 0 0
      ]
      numberOfRays 2
      aperture 1
    }
    DistanceSensor {
      translation -0.042 -0.02 0.063
      rotation -0.13928600826049622 0.7002140415268951 0.7002140415268951 -2.8648
      children [
        USE SENSOR
      ]
      name "ds3"
      lookupTable [
        0 1024 0
        0.05 1024 0
        0.15 0 0
      ]
      numberOfRays 2
      aperture 1
    }
    DistanceSensor {
      translation -0.02 -0.042 0.063
      rotation -0.4271968128991576 0.6393367199875204 0.6393367199875204 -2.33413
      children [
        USE SENSOR
      ]
      name "ds2"
      lookupTable [
        0 1024 0
        0.05 1024 0
        0.15 0 0
      ]
      numberOfRays 2
      aperture 1
    }
    Pose {
      translation 0 0 0.0415
      rotation 0 0 1 -1.570796
      children [
        Shape {
          appearance PBRAppearance {
            baseColor 0.0820075 0.364731 0.8
            roughness 1
            metalness 0
          }
          geometry DEF BODY Cylinder {
            height 0.08
            radius 0.045
          }
        }
      ]
    }
    HingeJoint {
      jointParameters HingeJointParameters {
        position 4516.660178397396
        axis 0 1 0
        anchor 0 0 0.025
      }
      device [
        RotationalMotor {
          name "left wheel motor"
          consumptionFactor 70
        }
        PositionSensor {
          name "left wheel sensor"
        }
      ]
      endPoint Solid {
        translation 0 0.04499999999999437 0.025
        rotation -0.497705048306232 0.4977051526231655 0.7103374310444599 4.376853316908857
        children [
          DEF WHEEL Pose {
            rotation 0.577656895078166 0.5771968951617173 -0.5771968951617173 -2.093935
            children [
              Shape {
                appearance PBRAppearance {
                  baseColor 1 0 0
                  roughness 1
                  metalness 0
                }
                geometry Cylinder {
                  height 0.01
                  radius 0.025
                }
              }
            ]
          }
        ]
        name "left wheel"
        boundingObject USE WHEEL
        physics DEF PHYSICS_WHEEL Physics {
          density -1
          mass 0.05
        }
      }
    }
    HingeJoint {
      jointParameters HingeJointParameters {
        position 5115.902272626811
        axis 0 1 0
        anchor 0 0 0.025
      }
      device [
        RotationalMotor {
          name "right wheel motor"
          consumptionFactor 70
        }
        PositionSensor {
          name "right wheel sensor"
        }
      ]
      endPoint Solid {
        translation 0 -0.0449999999999932 0.025
        rotation -0.566201404785873 0.5662013578705918 -0.5990258688604376 2.062186897384282
        children [
          USE WHEEL
        ]
        name "right wheel"
        boundingObject USE WHEEL
        physics USE PHYSICS_WHEEL
      }
    }
    DistanceSensor {
      translation 0.042 -0.02 0.063
      rotation -0.9626378392751118 0.19147896803009973 0.19147896803009973 -1.60886
      children [
        DEF SENSOR Pose {
          rotation 0.577656895078166 0.5771968951617173 -0.5771968951617173 -2.093935
          children [
            Shape {
              appearance PBRAppearance {
                baseColor 0.975691 0.981481 0.0252992
                roughness 1
                metalness 0
              }
              geometry Cylinder {
                height 0.004
                radius 0.008
              }
            }
          ]
        }
      ]
      name "ds0"
      lookupTable [
        0 1024 0
        0.05 1024 0
        0.15 0 0
      ]
      aperture 1
    }
    DistanceSensor {
      translation 0.02 -0.042 0.063
      rotation -0.7268313515069925 0.4856522348690052 0.4856522348690052 -1.88458
      children [
        USE SENSOR
      ]
      name "ds1"
      lookupTable [
        0 1024 0
        0.05 1024 0
        0.15 0 0
      ]
      numberOfRays 2
      aperture 1
    }
    DEF SMILE Pose {
      translation 0.036 0 0.025
      rotation 0.25056300542381216 -0.9351130202419243 -0.25056300542381216 1.637834
      children [
        Shape {
          appearance PBRAppearance {
            baseColor 0.721569 0.290196 0.290196
            roughness 1
            metalness 0
          }
          geometry Cylinder {
            height 0.018
            radius 0.009
            subdivision 3
          }
        }
      ]
    }
  ]
  name "robot_1"
  boundingObject Pose {
    translation 0 0 0.0415
    rotation 0 0 1 -1.570796
    children [
      USE BODY
    ]
  }
  physics Physics {
    density -1
    mass 0.5
  }
  controller "robot_controller"
}
DEF robot_2 Robot {
  translation -0.8609682131626979 0.5619718828068649 -0.00046861931086070174
  rotation -0.01160149784995431 -0.011960685456928726 -0.9998611639877998 1.54133174607665
  children [
    DistanceSensor {
      translation 0.02 0.042 0.063
      rotation -0.7268299363531201 -0.48565329383260614 -0.48565329383260614 -1.88458
      children [
        DEF SENSOR Pose {
          rotation 0.577656895078166 0.5771968951617173 -0.5771968951617173 -2.093935
          children [
            Shape {
              appearance PBRAppearance {
                baseColor 0.975691 0.981481 0.0252992
                roughness 1
                metalness 0
              }
              geometry Cylinder {
                height 0.004
                radius 0.008
              }
            }
          ]
        }
      ]
      name "ds6"
      lookupTable [
        0 1024 0
        0.05 1024 0
        0.15 0 0
      ]
      numberOfRays 2
      aperture 1
    }
    DistanceSensor {
      translation 0.042 0.02 0.063
      rotation -0.9626362180015103 -0.19148304336382932 -0.19148304336382932 -1.60887
      children [
        DEF SENSOR Pose {
          rotation 0.577656895078166 0.5771968951617173 -0.5771968951617173 -2.093935
          children [
            Shape {
              appearance PBRAppearance {
                baseColor 0.975691 0.981481 0.0252992
                roughness 1
                metalness 0
              }
              geometry Cylinder {
                height 0.004
                radius 0.008
              }
            }
          ]
        }
      ]
      name "ds7"
      lookupTable [
        0 1024 0
        0.05 1024 0
        0.15 0 0
      ]
      numberOfRays 2
      aperture 1
    }
    DistanceSensor {
      translation -0.02 0.042 0.063
      rotation -0.42718918036721304 -0.6393392699409246 -0.6393392699409246 -2.33415
      children [
        USE SENSOR
      ]
      name "ds5"
      lookupTable [
        0 1024 0
        0.05 1024 0
        0.15 0 0
      ]
      numberOfRays 2
      aperture 1
    }
    DistanceSensor {
      translation -0.042 0.02 0.063
      rotation -0.13927796840242873 -0.7002148411443777 -0.7002148411443777 -2.86482
      children [
        USE SENSOR
      ]
      name "ds4"
      lookupTable [
        0 1024 0
        0.05 1024 0
        0.15 0 0
      ]
      numberOfRays 2
      aperture 1
    }
    DistanceSensor {
      translation -0.042 -0.02 0.063
      rotation -0.13928600826049622 0.7002140415268951 0.7002140415268951 -2.8648
      children [
        USE SENSOR
      ]
      name "ds3"
      lookupTable [
        0 1024 0
        0.05 1024 0
        0.15 0 0
      ]
      numberOfRays 2
      aperture 1
    }
    DistanceSensor {
      translation -0.02 -0.042 0.063
      rotation -0.4271968128991576 0.6393367199875204 0.6393367199875204 -2.33413
      children [
        USE SENSOR
      ]
      name "ds2"
      lookupTable [
        0 1024 0
        0.05 1024 0
        0.15 0 0
      ]
      numberOfRays 2
      aperture 1
    }
    Pose {
      translation 0 0 0.0415
      rotation 0 0 1 -1.570796
      children [
        Shape {
          appearance PBRAppearance {
            baseColor 0.0820075 0.364731 0.8
            roughness 1
            metalness 0
          }
          geometry DEF BODY Cylinder {
            height 0.08
            radius 0.045
          }
        }
      ]
    }
    HingeJoint {
      jointParameters HingeJointParameters {
        position 4030.945400719762
        axis 0 1 0
        anchor 0 0 0.025
      }
      device [
        RotationalMotor {
          name "left wheel motor"
          consumptionFactor 70
        }
        PositionSensor {
          name "left wheel sensor"
        }
      ]
      endPoint Solid {
        translation 0 0.04499999999999401 0.025
        rotation 0.7071024913256921 -0.7071026754264347 -0.0034457460408115924 3.134701136515073
        children [
          DEF WHEEL Pose {
            rotation 0.577656895078166 0.5771968951617173 -0.5771968951617173 -2.093935
            children [
              Shape {
                appearance PBRAppearance {
                  baseColor 1 0 0
                  roughness 1
                  metalness 0
                }
                geometry Cylinder {
                  height 0.01
                  radius 0.025
                }
              }
            ]
          }
        ]
        name "left wheel"
        boundingObject USE WHEEL
        physics DEF PHYSICS_WHEEL Physics {
          density -1
          mass 0.05
        }
      }
    }
    HingeJoint {
      jointParameters HingeJointParameters {
        position 5465.401836519627
        axis 0 1 0
        anchor 0 0 0.025
      }
      device [
        RotationalMotor {
          name "right wheel motor"
          consumptionFactor 70
        }
        PositionSensor {
          name "right wheel sensor"
        }
      ]
      endPoint Solid {
        translation 0 -0.04499999999999316 0.025
        rotation 0.37914878254725226 -0.3791487442138834 -0.8440926669827026 1.7394836584531626
        children [
          USE WHEEL
        ]
        name "right wheel"
        boundingObject USE WHEEL
        physics USE PHYSICS_WHEEL
      }
    }
    DistanceSensor {
      translation 0.042 -0.02 0.063
      rotation -0.9626378392751118 0.19147896803009973 0.19147896803009973 -1.60886
      children [
        DEF SENSOR Pose {
          rotation 0.577656895078166 0.5771968951617173 -0.5771968951617173 -2.093935
          children [
            Shape {
              appearance PBRAppearance {
                baseColor 0.975691 0.981481 0.0252992
                roughness 1
                metalness 0
              }
              geometry Cylinder {
                height 0.004
                radius 0.008
              }
            }
          ]
        }
      ]
      name "ds0"
      lookupTable [
        0 1024 0
        0.05 1024 0
        0.15 0 0
      ]
      aperture 1
    }
    DistanceSensor {
      translation 0.02 -0.042 0.063
      rotation -0.7268313515069925 0.4856522348690052 0.4856522348690052 -1.88458
      children [
        USE SENSOR
      ]
      name "ds1"
      lookupTable [
        0 1024 0
        0.05 1024 0
        0.15 0 0
      ]
      numberOfRays 2
      aperture 1
    }
    DEF SMILE Pose {
      translation 0.036 0 0.025
      rotation 0.25056300542381216 -0.9351130202419243 -0.25056300542381216 1.637834
      children [
        Shape {
          appearance PBRAppearance {
            baseColor 0.721569 0.290196 0.290196
            roughness 1
            metalness 0
          }
          geometry Cylinder {
            height 0.018
            radius 0.009
            subdivision 3
          }
        }
      ]
    }
  ]
  name "robot_2"
  boundingObject Pose {
    translation 0 0 0.0415
    rotation 0 0 1 -1.570796
    children [
      USE BODY
    ]
  }
  physics Physics {
    density -1
    mass 0.5
  }
  controller "robot_controller"
}
Robot {
  translation 0 0 0.001
  children [
    Display {
      children [
        Shape {
          appearance PBRAppearance {
            baseColorMap ImageTexture {
            }
            roughness 1
          }
          geometry Plane {
            size 2 2
          }
        }
      ]
    }
  ]
  name "supervisor"
  controller "Robot_Supervisor"
  supervisor TRUE
}
Solid {
  translation 0.107907 0.500187 0.05
  children [
    Shape {
      appearance PBRAppearance {
        baseColor 0 0 0
        metalness 0
      }
      geometry Box {
        size 0.05 1 0.1
      }
    }
  ]
  boundingObject Box {
    size 0.05 1 0.1
  }
}
Solid {
  translation -0.169068 -0.654144 0.05
  rotation 0 0 1 -3.1415853071795863
  children [
    Shape {
      appearance PBRAppearance {
        baseColor 0 0 0
        metalness 0
      }
      geometry Box {
        size 0.05 0.7 0.1
      }
    }
  ]
  name "solid(2)"
  boundingObject Box {
    size 0.05 0.7 0.1
  }
}
Solid {
  translation 0.6481 -0.345055 0.05
  rotation 0 0 -1 1.57079
  children [
    Shape {
      appearance PBRAppearance {
        baseColor 0 0 0
        metalness 0
      }
      geometry Box {
        size 0.05 0.7 0.1
      }
    }
  ]
  name "solid(3)"
  boundingObject Box {
    size 0.05 0.7 0.1
  }
}
E-puck {
  translation -0.732163 -0.702254 -0.000113893
  rotation 9.353469910646897e-05 -0.00010176999902779767 -0.9999999904470637 0.0349446
  controller "rrt_star_heuristic"
  turretSlot [
    InertialUnit {
    }
    GPS {
    }
  ]
}
